{"errorMessage": "An error occurred (InvalidRequestException) when calling the StartFileTransfer operation: Invalid LocalDirectoryPath.", "errorType": "InvalidRequestException", "requestId": "aa470556-e500-433c-b8bb-ca7e93431b55", "stackTrace": ["  File \"/var/task/index.py\", line 88, in handler\n    raise e\n", "  File \"/var/task/index.py\", line 51, in handler\n    transfer_response = transfer_client.start_file_transfer(\n", "  File \"/var/runtime/botocore/client.py\", line 598, in _api_call\n    return self._make_api_call(operation_name, kwargs)\n", "  File \"/var/runtime/botocore/context.py\", line 123, in wrapper\n    return func(*args, **kwargs)\n", "  File \"/var/runtime/botocore/client.py\", line 1061, in _make_api_call\n    raise error_class(parsed_response, operation_name)\n"]}